Workbook

Sheet Clean cases
A1: Patient | D1: Symptoms (model inputs) | W1: First-visit tests (model inputs) | AG1: Confirmation tests – NOT model inputs | AK1: Outcome | AN1: Data check
A2: Case # | B2: Gender | C2: Age (years) | D2: Joint / back pain | E2: Night sweats | F2: Fever / fatigue | G2: Abdominal pain | H2: Chronic diarrhea | I2: Nausea / vomiting | J2: Weight loss | K2: Enlarged spleen | L2: Enlarged liver | M2: Jaundice | N2: Enlarged lymph nodes | O2: Blocked nose | P2: Dry cough | Q2: Oral ulcers | R2: Nerve pain / numbness | S2: Shortness of breath | T2: Muscle pain | U2: Palpitations / heart block | V2: Skin lesions / itching | W2: Chest X-ray | X2: Imaging: enlarged chest lymph nodes | Y2: Imaging: lung nodules / infiltrates | Z2: ACE (U/L) | AA2: ACE reported as | AB2: CRP (mg/L) | AC2: LDH (U/L) | AD2: WBC (×10³/µL) | AE2: Heart tests abnormal (ECG / echo / MRI) | AF2: Liver tests abnormal | AG2: TB test | AH2: Biopsy site | AI2: Biopsy result | AJ2: BALF CD4/CD8 | AK2: Final diagnosis | AL2: Sarcoidosis? | AM2: Diagnostic time (months) | AN2: To check
A3: 1 | B3: Male | C3: 56 | D3: Not checked | E3: Not checked | F3: Yes | G3: Not checked | H3: Not checked | I3: Not checked | J3: Not checked | K3: Not checked | L3: Not checked | M3: Not checked | N3: No | O3: Not checked | P3: No | Q3: No | R3: Not checked | S3: Not checked | T3: Not checked | U3: Not checked | V3: Not checked | W3: Not done | X3: Not checked | Y3: Not checked | AA3: Not done | AE3: Not checked | AF3: Not checked | AG3: Not done | AI3: Not done | AK3: Tularemia | AL3: No | AM3: 1 | AN3: Looks like the same patient as case 29 (Tularemia, 56 M, 4 weeks) – merge or delete one
A4: 2 | B4: Female | C4: 55 | D4: Not checked | E4: Not checked | F4: Yes | G4: Not checked | H4: Not checked | I4: Not checked | J4: Not checked | K4: Not checked | L4: Yes | M4: Not checked | N4: No | O4: Not checked | P4: No | Q4: No | R4: Not checked | S4: Not checked | T4: Not checked | U4: Not checked | V4: Not checked | W4: Not done | X4: Not checked | Y4: Not checked | AA4: Not done | AE4: Not checked | AF4: Not checked | AG4: Not done | AI4: Not done | AK4: Cat scratch disease | AL4: No | AM4: 5 | AN4: Looks like the same patient as case 30 (Cat scratch, 55 F, 5 months) – merge or delete one
A5: 3 | B5: Male | C5: 45 | D5: Not checked | E5: Not checked | F5: Yes | G5: Not checked | H5: Not checked | I5: Not checked | J5: Yes | K5: Not checked | L5: No | M5: Not checked | N5: Yes | O5: Yes | P5: No | Q5: No | R5: Not checked | S5: Not checked | T5: Not checked | U5: Not checked | V5: Not checked | W5: Not done | X5: Not checked | Y5: Not checked | AA5: Not done | AE5: Not checked | AF5: Not checked | AG5: Not done | AI5: Not done | AK5: Hodgkin’s lymphoma | AL5: No | AM5: 24
A6: 4 | B6: Female | C6: 56 | D6: Not checked | E6: Not checked | F6: Yes | G6: Not checked | H6: Not checked | I6: Not checked | J6: Not checked | K6: Not checked | L6: No | M6: Not checked | N6: No | O6: No | P6: No | Q6: No | R6: Not checked | S6: Not checked | T6: Not checked | U6: Not checked | V6: Not checked | W6: Not done | X6: Not checked | Y6: Not checked | AA6: Not done | AE6: Not checked | AF6: Not checked | AG6: Not done | AI6: Not done | AK6: Biclonal Lymphoma | AL6: No | AM6: 72
A7: 5 | B7: Male | C7: 70 | D7: Not checked | E7: Not checked | F7: Yes | G7: Not checked | H7: Not checked | I7: Not checked | J7: Not checked | K7: Not checked | L7: No | M7: Not checked | N7: No | O7: No | P7: Yes | Q7: Yes | R7: Not checked | S7: Not checked | T7: Not checked | U7: Not checked | V7: Not checked | W7: Not done | X7: No | Y7: Yes | AA7: Normal | AB7: 16.9 | AE7: Not checked | AF7: Not checked | AG7: Positive | AH7: Gingiva (oral) | AI7: Non-caseating granuloma | AK7: pulmonary tuberculosis | AL7: No | AM7: 10
A8: 6 | B8: Male | C8: 66 | D8: Not checked | E8: Not checked | F8: Yes | G8: Not checked | H8: Not checked | I8: Not checked | J8: Not checked | K8: Not checked | L8: No | M8: Not checked | N8: No | O8: No | P8: Yes | Q8: No | R8: Yes | S8: Not checked | T8: Yes | U8: Not checked | V8: Yes | W8: Normal | X8: Yes | Y8: Yes | Z8: 36.9 | AA8: Number given | AB8: 100 | AC8: 284 | AE8: Not checked | AF8: Not checked | AG8: Negative | AH8: Cervical + mediastinal lymph node | AI8: Other finding | AJ8: 1.27 | AK8: Hodgkin’s lymphoma | AL8: No | AM8: 2 | AN8: CRP was a range (100–220); used 100
A9: 7 | B9: Female | C9: 0.75 | D9: Not checked | E9: Not checked | F9: Yes | G9: Not checked | H9: Not checked | I9: Not checked | J9: Not checked | K9: Not checked | L9: Not checked | M9: Not checked | N9: Not checked | O9: Not checked | P9: Not checked | Q9: Not checked | R9: Not checked | S9: Not checked | T9: No | U9: Not checked | V9: Yes | W9: Not done | X9: No | Y9: No | Z9: 14.2 | AA9: Number given | AB9: 6.56 | AD9: 15 | AE9: Not checked | AF9: Not checked | AG9: Negative | AH9: Skin | AI9: Non-caseating granuloma | AK9: Early-Onset Sarcoidosis (EOS) | AL9: Yes | AM9: 8 | AN9: Age 9 months = 0.75 years. WBC 15000 converted to 15.0 (×10³/µL)
A10: 8 | B10: Female | C10: 45 | D10: Not checked | E10: Not checked | F10: Yes | G10: Yes | H10: Yes | I10: Not checked | J10: Yes | K10: Not checked | L10: Not checked | M10: Not checked | N10: Not checked | O10: Not checked | P10: Not checked | Q10: Not checked | R10: Not checked | S10: Not checked | T10: Not checked | U10: Not checked | V10: Not checked | W10: Not done | X10: Yes | Y10: No | AA10: Not done | AE10: Not checked | AF10: Not checked | AG10: Not done | AH10: Kidney + spleen | AI10: Non-caseating granuloma | AK10: Whipple’s Disease | AL10: No | AM10: 60
A11: 9 | B11: Male | C11: 58 | D11: Not checked | E11: Not checked | F11: No | G11: No | H11: No | I11: Not checked | J11: No | K11: Not checked | L11: No | M11: Not checked | N11: No | O11: No | P11: No | Q11: No | R11: No | S11: Yes | T11: No | U11: Not checked | V11: No | W11: Not done | X11: Yes | Y11: Not checked | AA11: Not done | AE11: Yes | AF11: Not checked | AG11: Not done | AH11: Lymph node (EBUS) | AI11: No granuloma | AK11: Biventricular Arrhythmogenic Cardiomyopathy (AC) | AL11: No | AM11: 1
A12: 10 | B12: Male | C12: 50 | D12: Not checked | E12: Not checked | F12: No | G12: No | H12: No | I12: Not checked | J12: No | K12: Not checked | L12: No | M12: Not checked | N12: No | O12: No | P12: No | Q12: No | R12: No | S12: Yes | T12: No | U12: Yes | V12: No | W12: Not done | X12: Not checked | Y12: Not checked | AA12: Not done | AE12: Yes | AF12: Not checked | AG12: Not done | AI12: Not done | AK12: Genetic Dilated Cardiomyopathy | AL12: No | AM12: 24
A13: 11 | B13: Female | C13: 42 | D13: Yes | E13: Yes | F13: Yes | G13: No | H13: No | I13: Not checked | J13: No | K13: Not checked | L13: No | M13: Not checked | N13: No | O13: No | P13: No | Q13: No | R13: No | S13: No | T13: No | U13: No | V13: No | W13: Not done | X13: Yes | Y13: Yes | Z13: 70 | AA13: Number given | AE13: Not checked | AF13: Not checked | AG13: Not done | AH13: Lymph node + iliac bone | AI13: Non-caseating granuloma | AK13: Multisystem Sarcoidosis with Axial Skeleton Involvement | AL13: Yes | AM13: 6
A14: 12 | B14: Female | C14: 44 | D14: Yes | E14: No | F14: No | G14: No | H14: No | I14: Not checked | J14: No | K14: Not checked | L14: No | M14: Not checked | N14: No | O14: No | P14: No | Q14: No | R14: No | S14: No | T14: No | U14: No | V14: Yes | W14: Not done | X14: No | Y14: No | AA14: Not done | AE14: Not checked | AF14: Not checked | AG14: Not done | AH14: Skin (gluteal ulcer) | AI14: Non-caseating granuloma | AK14: Isolated Ulcerative Cutaneous Sarcoidosis | AL14: Yes | AM14: 2 | AN14: Skin column was "No" but the disease is a skin ulcer – set to Yes. Please confirm
A15: 13 | B15: Female | C15: 71 | D15: Not checked | E15: Not checked | F15: Not checked | G15: Not checked | H15: Not checked | I15: Not checked | J15: Not checked | K15: Not checked | L15: Not checked | M15: Not checked | N15: Not checked | O15: Not checked | P15: Not checked | Q15: Not checked | R15: Not checked | S15: Not checked | T15: Not checked | U15: Yes | V15: Not checked | W15: Not done | X15: Yes | Y15: Not checked | AA15: Normal | AE15: Yes | AF15: Not checked | AG15: Not done | AH15: Lymph node (EBUS) | AI15: Non-caseating granuloma | AK15: Cardiac Sarcoidosis with Ulcerative Colitis | AL15: Yes | AM15: 156
A16: 14 | B16: Female | C16: 70 | D16: No | E16: No | F16: Yes | G16: No | H16: No | I16: Not checked | J16: Not checked | K16: Not checked | L16: Not checked | M16: Not checked | N16: Not checked | O16: Not checked | P16: Not checked | Q16: Not checked | R16: Not checked | S16: Yes | T16: Not checked | U16: Yes | V16: Not checked | W16: Not done | X16: Not checked | Y16: Not checked | AA16: Not done | AE16: Yes | AF16: Not checked | AG16: Not done | AH16: Lymph node | AI16: Non-caseating granuloma | AJ16: 9.04 | AK16: Cardiac Sarcoidosis | AL16: Yes | AM16: 36
A17: 15 | B17: Female | C17: 69 | D17: Not checked | E17: Not checked | F17: Not checked | G17: Yes | H17: Not checked | I17: Not checked | J17: Not checked | K17: Not checked | L17: Not checked | M17: Not checked | N17: Not checked | O17: Not checked | P17: Not checked | Q17: Not checked | R17: Not checked | S17: Not checked | T17: Not checked | U17: Not checked | V17: Not checked | W17: Not done | X17: Not checked | Y17: Not checked | AA17: Not done | AE17: Not checked | AF17: Not checked | AG17: Not done | AH17: Liver | AI17: Inconclusive | AK17: Hepatic Sarcoidosis | AL17: Yes | AN17: Diagnostic time "not determined" – left empty. Biopsy inconclusive: how was it confirmed?
A18: 16 | B18: Male | C18: 45 | D18: Not checked | E18: Not checked | F18: Yes | G18: No | H18: Not checked | I18: Not checked | J18: Yes | K18: Not checked | L18: Not checked | M18: Not checked | N18: Not checked | O18: Not checked | P18: Not checked | Q18: Not checked | R18: Not checked | S18: Yes | T18: Not checked | U18: Yes | V18: Not checked | W18: Not done | X18: Not checked | Y18: Yes | AA18: Not done | AE18: Not checked | AF18: Not checked | AG18: Negative | AH18: Lung | AI18: Non-caseating granuloma | AK18: Pleuroparenchymal Sarcoidosis | AL18: Yes | AN18: Diagnostic time "3 weeks after failed TB treatment" – how many months from first symptom?
A19: 17 | B19: Female | C19: 26 | D19: Yes | E19: Not checked | F19: Not checked | G19: Not checked | H19: Not checked | I19: Not checked | J19: Not checked | K19: Not checked | L19: Not checked | M19: Not checked | N19: Not checked | O19: Not checked | P19: Not checked | Q19: Not checked | R19: Not checked | S19: Not checked | T19: Not checked | U19: Not checked | V19: Yes | W19: Not done | X19: Not checked | Y19: Not checked | AA19: Not done | AE19: Not checked | AF19: Not checked | AG19: Not done | AH19: Skin | AI19: Non-caseating granuloma | AK19: PPD-like Sarcoidosis | AL19: Yes | AM19: 12
A20: 18 | B20: Male | C20: 39 | D20: Not checked | E20: Yes | F20: Yes | G20: Yes | H20: Not checked | I20: Not checked | J20: Not checked | K20: Not checked | L20: Not checked | M20: Not checked | N20: Yes | O20: Not checked | P20: Not checked | Q20: Not checked | R20: Not checked | S20: Not checked | T20: Not checked | U20: Not checked | V20: Yes | W20: Normal | X20: No | Y20: Not checked | AA20: Normal | AE20: Yes | AF20: Not checked | AG20: Not done | AH20: Skin (tattoo) | AI20: Non-caseating granuloma | AK20: Tattoo Sarcoidosis with coexisting nonspecific myocarditis | AL20: Yes | AM20: 2 | AN20: Tattoo skin lesions not marked in the skin column – set to Yes. Please confirm
A21: 19 | B21: Female | C21: 56 | D21: No | E21: No | F21: No | G21: No | H21: Yes | I21: Yes | J21: No | K21: Not checked | L21: No | M21: Yes | N21: No | O21: No | P21: Yes | Q21: No | R21: No | S21: Yes | T21: Not checked | U21: Not checked | V21: No | W21: Not done | X21: Yes | Y21: Yes | AA21: Not done | AE21: Not checked | AF21: Not checked | AG21: Not done | AH21: Lymph node (EBUS) | AI21: Non-caseating granuloma | AK21: Pancreatic Sarcoidosis | AL21: Yes | AM21: 5
A22: 20 | B22: Female | C22: 56 | D22: Yes | E22: No | F22: No | G22: No | H22: No | I22: Yes | J22: No | K22: Not checked | L22: No | M22: Yes | N22: No | O22: No | P22: No | Q22: No | R22: No | S22: No | T22: No | U22: No | V22: No | W22: Not done | X22: Not checked | Y22: Not checked | AA22: Not done | AE22: Not checked | AF22: Yes | AG22: Not done | AH22: Porta hepatis node + bile duct | AI22: Non-caseating granuloma | AK22: Biliary Sarcoidosis | AL22: Yes | AN22: Diagnostic time "several weeks" – need a number
A23: 21 | B23: Female | C23: 64 | D23: Not checked | E23: Not checked | F23: Not checked | G23: Not checked | H23: Not checked | I23: Not checked | J23: Not checked | K23: Not checked | L23: Not checked | M23: Not checked | N23: Not checked | O23: Yes | P23: Not checked | Q23: Not checked | R23: Not checked | S23: Yes | T23: Not checked | U23: Not checked | V23: Not checked | W23: Not done | X23: Not checked | Y23: Not checked | AA23: Not done | AE23: Not checked | AF23: Not checked | AG23: Not done | AH23: Nose | AI23: Non-caseating granuloma | AK23: Sinonasal Sarcoidosis | AL23: Yes | AM23: 6
A24: 22 | B24: Male | C24: 54 | D24: Yes | E24: Not checked | F24: Not checked | G24: Yes | H24: Not checked | I24: Not checked | J24: Not checked | K24: Not checked | L24: Not checked | M24: Not checked | N24: Not checked | O24: Not checked | P24: Yes | Q24: Not checked | R24: Not checked | S24: Not checked | T24: Not checked | U24: Not checked | V24: No | W24: Not done | X24: Yes | Y24: Yes | Z24: 102.2 | AA24: Number given | AE24: Not checked | AF24: Not checked | AG24: Not done | AH24: Liver | AI24: Non-caseating granuloma | AK24: Multisystem Sarcoidosis (Pulmonary, Hepatic, Osseous, Lymphatic, Adrenal) | AL24: Yes | AM24: 1 | AN24: CRP written as -52 (negative is impossible) – removed, please check the value
A25: 23 | B25: Female | C25: 85 | D25: No | E25: Not checked | F25: Not checked | G25: Not checked | H25: Not checked | I25: Not checked | J25: Not checked | K25: Not checked | L25: Not checked | M25: Not checked | N25: Not checked | O25: Not checked | P25: Not checked | Q25: Not checked | R25: Not checked | S25: Not checked | T25: Not checked | U25: Not checked | V25: Yes | W25: Not done | X25: Not checked | Y25: Not checked | AA25: Not done | AE25: Not checked | AF25: Not checked | AG25: Not done | AH25: Skin (melanoma) | AI25: Other finding | AK25: Osseous Sarcoidosis of the fibula | AL25: Yes | AM25: 6 | AN25: Age "80s" – used 85. Biopsy listed is melanoma; is there a bone biopsy that confirmed sarcoidosis?
A26: 24 | B26: Female | C26: 48 | D26: Yes | E26: Not checked | F26: Yes | G26: No | H26: Not checked | I26: Not checked | J26: Not checked | K26: Not checked | L26: Not checked | M26: Not checked | N26: Not checked | O26: Not checked | P26: Not checked | Q26: Yes | R26: Not checked | S26: Not checked | T26: Not checked | U26: Not checked | V26: Yes | W26: Normal | X26: No | Y26: No | Z26: 60 | AA26: Number given | AE26: Not checked | AF26: Not checked | AG26: Not done | AH26: Skin + gum + lip | AI26: Non-caseating granuloma | AK26: Cutaneous and Oral Sarcoidosis | AL26: Yes | AM26: 12
A27: 25 | B27: Female | D27: Yes | E27: Not checked | F27: Yes | G27: Yes | H27: Not checked | I27: Not checked | J27: Not checked | K27: Yes | L27: Not checked | M27: Not checked | N27: Not checked | O27: Not checked | P27: Not checked | Q27: Not checked | R27: Not checked | S27: Not checked | T27: Not checked | U27: Not checked | V27: Not checked | W27: Not done | X27: Not checked | Y27: Not checked | AA27: Not done | AE27: Not checked | AF27: Not checked | AG27: Not done | AI27: Not done | AK27: Isolated Splenic Sarcoidosis | AL27: Yes | AN27: Age "adult" and diagnostic time "not determined" – need numbers if available
A28: 26 | B28: Female | C28: 66 | D28: No | E28: No | F28: Yes | G28: No | H28: No | I28: Yes | J28: Yes | K28: No | L28: Not checked | M28: Not checked | N28: Not checked | O28: Not checked | P28: Not checked | Q28: Not checked | R28: Not checked | S28: Not checked | T28: Not checked | U28: Not checked | V28: Not checked | W28: Not done | X28: No | Y28: No | AA28: Not done | AE28: Not checked | AF28: Not checked | AG28: Not done | AH28: Bone marrow + tissue | AI28: Granuloma (type not stated) | AK28: Hepato-Splenic Sarcoidosis | AL28: Yes | AM28: 2
A29: 27 | B29: Male | C29: 35 | D29: No | E29: No | F29: No | G29: No | H29: No | I29: No | J29: No | K29: No | L29: No | M29: No | N29: No | O29: No | P29: Yes | Q29: No | R29: No | S29: Yes | T29: No | U29: No | V29: No | W29: Not done | X29: Yes | Y29: Yes | AA29: Not done | AE29: Not checked | AF29: Not checked | AG29: Not done | AH29: Lung | AI29: Non-caseating granuloma | AK29: Pulmonary Sarcoidosis | AL29: Yes | AN29: Age "30s" – used 35. 180 months is time on Infliximab, not diagnostic delay – need real delay
A30: 28 | B30: Male | C30: 47 | D30: Not checked | E30: Not checked | F30: Not checked | G30: Yes | H30: No | I30: Yes | J30: Yes | K30: Not checked | L30: Not checked | M30: Yes | N30: Not checked | O30: Not checked | P30: Yes | Q30: Not checked | R30: Not checked | S30: Yes | T30: No | U30: Not checked | V30: Not checked | W30: Not done | X30: Not checked | Y30: Not checked | AA30: Not done | AE30: Not checked | AF30: Not checked | AG30: Not done | AH30: Pancreas + lymph node | AI30: Non-caseating granuloma | AK30: Multisystem Sarcoidosis | AL30: Yes | AM30: 4 | AN30: Already diagnosed 10 years earlier (relapse case) – used 4 months of current symptoms
A31: 29 | B31: Male | C31: 56 | D31: Not checked | E31: Not checked | F31: Not checked | G31: Yes | H31: Not checked | I31: Not checked | J31: Not checked | K31: Not checked | L31: Not checked | M31: Not checked | N31: Not checked | O31: Not checked | P31: Not checked | Q31: Not checked | R31: Not checked | S31: Not checked | T31: Not checked | U31: Not checked | V31: Not checked | W31: Not done | X31: Yes | Y31: Yes | AA31: Not done | AE31: Not checked | AF31: Not checked | AG31: Not done | AI31: Not done | AK31: Tularemia | AL31: No | AM31: 1 | AN31: Possible duplicate of case 1
A32: 30 | B32: Female | C32: 55 | D32: Not checked | E32: Yes | F32: Yes | G32: Not checked | H32: Not checked | I32: Not checked | J32: Not checked | K32: Not checked | L32: Not checked | M32: Not checked | N32: Yes | O32: Not checked | P32: Not checked | Q32: Not checked | R32: Not checked | S32: Not checked | T32: Not checked | U32: Not checked | V32: Not checked | W32: Not done | X32: Not checked | Y32: Not checked | AA32: Not done | AE32: Not checked | AF32: Not checked | AG32: Not done | AI32: Not done | AK32: Cat Scratch Disease | AL32: No | AM32: 5 | AN32: Possible duplicate of case 2

Sheet Quick stats
A1: Symptom / finding | B1: Sarcoidosis: Yes | C1: Sarcoidosis: checked | D1: % in sarcoidosis | E1: Other diseases: Yes | F1: Other diseases: checked | G1: % in other diseases
A2: Joint / back pain | B2: =COUNTIFS('Clean cases'!$D$3:$D$32,"Yes",'Clean cases'!$AL$3:$AL$32,"Yes") | C2: =COUNTIFS('Clean cases'!$D$3:$D$32,"<>Not checked",'Clean cases'!$AL$3:$AL$32,"Yes") | D2: =IF(C2=0,"-",B2/C2) | E2: =COUNTIFS('Clean cases'!$D$3:$D$32,"Yes",'Clean cases'!$AL$3:$AL$32,"No") | F2: =COUNTIFS('Clean cases'!$D$3:$D$32,"<>Not checked",'Clean cases'!$AL$3:$AL$32,"No") | G2: =IF(F2=0,"-",E2/F2)
A3: Night sweats | B3: =COUNTIFS('Clean cases'!$E$3:$E$32,"Yes",'Clean cases'!$AL$3:$AL$32,"Yes") | C3: =COUNTIFS('Clean cases'!$E$3:$E$32,"<>Not checked",'Clean cases'!$AL$3:$AL$32,"Yes") | D3: =IF(C3=0,"-",B3/C3) | E3: =COUNTIFS('Clean cases'!$E$3:$E$32,"Yes",'Clean cases'!$AL$3:$AL$32,"No") | F3: =COUNTIFS('Clean cases'!$E$3:$E$32,"<>Not checked",'Clean cases'!$AL$3:$AL$32,"No") | G3: =IF(F3=0,"-",E3/F3)
A4: Fever / fatigue | B4: =COUNTIFS('Clean cases'!$F$3:$F$32,"Yes",'Clean cases'!$AL$3:$AL$32,"Yes") | C4: =COUNTIFS('Clean cases'!$F$3:$F$32,"<>Not checked",'Clean cases'!$AL$3:$AL$32,"Yes") | D4: =IF(C4=0,"-",B4/C4) | E4: =COUNTIFS('Clean cases'!$F$3:$F$32,"Yes",'Clean cases'!$AL$3:$AL$32,"No") | F4: =COUNTIFS('Clean cases'!$F$3:$F$32,"<>Not checked",'Clean cases'!$AL$3:$AL$32,"No") | G4: =IF(F4=0,"-",E4/F4)
A5: Abdominal pain | B5: =COUNTIFS('Clean cases'!$G$3:$G$32,"Yes",'Clean cases'!$AL$3:$AL$32,"Yes") | C5: =COUNTIFS('Clean cases'!$G$3:$G$32,"<>Not checked",'Clean cases'!$AL$3:$AL$32,"Yes") | D5: =IF(C5=0,"-",B5/C5) | E5: =COUNTIFS('Clean cases'!$G$3:$G$32,"Yes",'Clean cases'!$AL$3:$AL$32,"No") | F5: =COUNTIFS('Clean cases'!$G$3:$G$32,"<>Not checked",'Clean cases'!$AL$3:$AL$32,"No") | G5: =IF(F5=0,"-",E5/F5)
A6: Chronic diarrhea | B6: =COUNTIFS('Clean cases'!$H$3:$H$32,"Yes",'Clean cases'!$AL$3:$AL$32,"Yes") | C6: =COUNTIFS('Clean cases'!$H$3:$H$32,"<>Not checked",'Clean cases'!$AL$3:$AL$32,"Yes") | D6: =IF(C6=0,"-",B6/C6) | E6: =COUNTIFS('Clean cases'!$H$3:$H$32,"Yes",'Clean cases'!$AL$3:$AL$32,"No") | F6: =COUNTIFS('Clean cases'!$H$3:$H$32,"<>Not checked",'Clean cases'!$AL$3:$AL$32,"No") | G6: =IF(F6=0,"-",E6/F6)
A7: Nausea / vomiting | B7: =COUNTIFS('Clean cases'!$I$3:$I$32,"Yes",'Clean cases'!$AL$3:$AL$32,"Yes") | C7: =COUNTIFS('Clean cases'!$I$3:$I$32,"<>Not checked",'Clean cases'!$AL$3:$AL$32,"Yes") | D7: =IF(C7=0,"-",B7/C7) | E7: =COUNTIFS('Clean cases'!$I$3:$I$32,"Yes",'Clean cases'!$AL$3:$AL$32,"No") | F7: =COUNTIFS('Clean cases'!$I$3:$I$32,"<>Not checked",'Clean cases'!$AL$3:$AL$32,"No") | G7: =IF(F7=0,"-",E7/F7)
A8: Weight loss | B8: =COUNTIFS('Clean cases'!$J$3:$J$32,"Yes",'Clean cases'!$AL$3:$AL$32,"Yes") | C8: =COUNTIFS('Clean cases'!$J$3:$J$32,"<>Not checked",'Clean cases'!$AL$3:$AL$32,"Yes") | D8: =IF(C8=0,"-",B8/C8) | E8: =COUNTIFS('Clean cases'!$J$3:$J$32,"Yes",'Clean cases'!$AL$3:$AL$32,"No") | F8: =COUNTIFS('Clean cases'!$J$3:$J$32,"<>Not checked",'Clean cases'!$AL$3:$AL$32,"No") | G8: =IF(F8=0,"-",E8/F8)
A9: Enlarged spleen | B9: =COUNTIFS('Clean cases'!$K$3:$K$32,"Yes",'Clean cases'!$AL$3:$AL$32,"Yes") | C9: =COUNTIFS('Clean cases'!$K$3:$K$32,"<>Not checked",'Clean cases'!$AL$3:$AL$32,"Yes") | D9: =IF(C9=0,"-",B9/C9) | E9: =COUNTIFS('Clean cases'!$K$3:$K$32,"Yes",'Clean cases'!$AL$3:$AL$32,"No") | F9: =COUNTIFS('Clean cases'!$K$3:$K$32,"<>Not checked",'Clean cases'!$AL$3:$AL$32,"No") | G9: =IF(F9=0,"-",E9/F9)
A10: Enlarged liver | B10: =COUNTIFS('Clean cases'!$L$3:$L$32,"Yes",'Clean cases'!$AL$3:$AL$32,"Yes") | C10: =COUNTIFS('Clean cases'!$L$3:$L$32,"<>Not checked",'Clean cases'!$AL$3:$AL$32,"Yes") | D10: =IF(C10=0,"-",B10/C10) | E10: =COUNTIFS('Clean cases'!$L$3:$L$32,"Yes",'Clean cases'!$AL$3:$AL$32,"No") | F10: =COUNTIFS('Clean cases'!$L$3:$L$32,"<>Not checked",'Clean cases'!$AL$3:$AL$32,"No") | G10: =IF(F10=0,"-",E10/F10)
A11: Jaundice | B11: =COUNTIFS('Clean cases'!$M$3:$M$32,"Yes",'Clean cases'!$AL$3:$AL$32,"Yes") | C11: =COUNTIFS('Clean cases'!$M$3:$M$32,"<>Not checked",'Clean cases'!$AL$3:$AL$32,"Yes") | D11: =IF(C11=0,"-",B11/C11) | E11: =COUNTIFS('Clean cases'!$M$3:$M$32,"Yes",'Clean cases'!$AL$3:$AL$32,"No") | F11: =COUNTIFS('Clean cases'!$M$3:$M$32,"<>Not checked",'Clean cases'!$AL$3:$AL$32,"No") | G11: =IF(F11=0,"-",E11/F11)
A12: Enlarged lymph nodes | B12: =COUNTIFS('Clean cases'!$N$3:$N$32,"Yes",'Clean cases'!$AL$3:$AL$32,"Yes") | C12: =COUNTIFS('Clean cases'!$N$3:$N$32,"<>Not checked",'Clean cases'!$AL$3:$AL$32,"Yes") | D12: =IF(C12=0,"-",B12/C12) | E12: =COUNTIFS('Clean cases'!$N$3:$N$32,"Yes",'Clean cases'!$AL$3:$AL$32,"No") | F12: =COUNTIFS('Clean cases'!$N$3:$N$32,"<>Not checked",'Clean cases'!$AL$3:$AL$32,"No") | G12: =IF(F12=0,"-",E12/F12)
A13: Blocked nose | B13: =COUNTIFS('Clean cases'!$O$3:$O$32,"Yes",'Clean cases'!$AL$3:$AL$32,"Yes") | C13: =COUNTIFS('Clean cases'!$O$3:$O$32,"<>Not checked",'Clean cases'!$AL$3:$AL$32,"Yes") | D13: =IF(C13=0,"-",B13/C13) | E13: =COUNTIFS('Clean cases'!$O$3:$O$32,"Yes",'Clean cases'!$AL$3:$AL$32,"No") | F13: =COUNTIFS('Clean cases'!$O$3:$O$32,"<>Not checked",'Clean cases'!$AL$3:$AL$32,"No") | G13: =IF(F13=0,"-",E13/F13)
A14: Dry cough | B14: =COUNTIFS('Clean cases'!$P$3:$P$32,"Yes",'Clean cases'!$AL$3:$AL$32,"Yes") | C14: =COUNTIFS('Clean cases'!$P$3:$P$32,"<>Not checked",'Clean cases'!$AL$3:$AL$32,"Yes") | D14: =IF(C14=0,"-",B14/C14) | E14: =COUNTIFS('Clean cases'!$P$3:$P$32,"Yes",'Clean cases'!$AL$3:$AL$32,"No") | F14: =COUNTIFS('Clean cases'!$P$3:$P$32,"<>Not checked",'Clean cases'!$AL$3:$AL$32,"No") | G14: =IF(F14=0,"-",E14/F14)
A15: Oral ulcers | B15: =COUNTIFS('Clean cases'!$Q$3:$Q$32,"Yes",'Clean cases'!$AL$3:$AL$32,"Yes") | C15: =COUNTIFS('Clean cases'!$Q$3:$Q$32,"<>Not checked",'Clean cases'!$AL$3:$AL$32,"Yes") | D15: =IF(C15=0,"-",B15/C15) | E15: =COUNTIFS('Clean cases'!$Q$3:$Q$32,"Yes",'Clean cases'!$AL$3:$AL$32,"No") | F15: =COUNTIFS('Clean cases'!$Q$3:$Q$32,"<>Not checked",'Clean cases'!$AL$3:$AL$32,"No") | G15: =IF(F15=0,"-",E15/F15)
A16: Nerve pain / numbness | B16: =COUNTIFS('Clean cases'!$R$3:$R$32,"Yes",'Clean cases'!$AL$3:$AL$32,"Yes") | C16: =COUNTIFS('Clean cases'!$R$3:$R$32,"<>Not checked",'Clean cases'!$AL$3:$AL$32,"Yes") | D16: =IF(C16=0,"-",B16/C16) | E16: =COUNTIFS('Clean cases'!$R$3:$R$32,"Yes",'Clean cases'!$AL$3:$AL$32,"No") | F16: =COUNTIFS('Clean cases'!$R$3:$R$32,"<>Not checked",'Clean cases'!$AL$3:$AL$32,"No") | G16: =IF(F16=0,"-",E16/F16)
A17: Shortness of breath | B17: =COUNTIFS('Clean cases'!$S$3:$S$32,"Yes",'Clean cases'!$AL$3:$AL$32,"Yes") | C17: =COUNTIFS('Clean cases'!$S$3:$S$32,"<>Not checked",'Clean cases'!$AL$3:$AL$32,"Yes") | D17: =IF(C17=0,"-",B17/C17) | E17: =COUNTIFS('Clean cases'!$S$3:$S$32,"Yes",'Clean cases'!$AL$3:$AL$32,"No") | F17: =COUNTIFS('Clean cases'!$S$3:$S$32,"<>Not checked",'Clean cases'!$AL$3:$AL$32,"No") | G17: =IF(F17=0,"-",E17/F17)
A18: Muscle pain | B18: =COUNTIFS('Clean cases'!$T$3:$T$32,"Yes",'Clean cases'!$AL$3:$AL$32,"Yes") | C18: =COUNTIFS('Clean cases'!$T$3:$T$32,"<>Not checked",'Clean cases'!$AL$3:$AL$32,"Yes") | D18: =IF(C18=0,"-",B18/C18) | E18: =COUNTIFS('Clean cases'!$T$3:$T$32,"Yes",'Clean cases'!$AL$3:$AL$32,"No") | F18: =COUNTIFS('Clean cases'!$T$3:$T$32,"<>Not checked",'Clean cases'!$AL$3:$AL$32,"No") | G18: =IF(F18=0,"-",E18/F18)
A19: Palpitations / heart block | B19: =COUNTIFS('Clean cases'!$U$3:$U$32,"Yes",'Clean cases'!$AL$3:$AL$32,"Yes") | C19: =COUNTIFS('Clean cases'!$U$3:$U$32,"<>Not checked",'Clean cases'!$AL$3:$AL$32,"Yes") | D19: =IF(C19=0,"-",B19/C19) | E19: =COUNTIFS('Clean cases'!$U$3:$U$32,"Yes",'Clean cases'!$AL$3:$AL$32,"No") | F19: =COUNTIFS('Clean cases'!$U$3:$U$32,"<>Not checked",'Clean cases'!$AL$3:$AL$32,"No") | G19: =IF(F19=0,"-",E19/F19)
A20: Skin lesions / itching | B20: =COUNTIFS('Clean cases'!$V$3:$V$32,"Yes",'Clean cases'!$AL$3:$AL$32,"Yes") | C20: =COUNTIFS('Clean cases'!$V$3:$V$32,"<>Not checked",'Clean cases'!$AL$3:$AL$32,"Yes") | D20: =IF(C20=0,"-",B20/C20) | E20: =COUNTIFS('Clean cases'!$V$3:$V$32,"Yes",'Clean cases'!$AL$3:$AL$32,"No") | F20: =COUNTIFS('Clean cases'!$V$3:$V$32,"<>Not checked",'Clean cases'!$AL$3:$AL$32,"No") | G20: =IF(F20=0,"-",E20/F20)
A21: Imaging: enlarged chest lymph nodes | B21: =COUNTIFS('Clean cases'!$X$3:$X$32,"Yes",'Clean cases'!$AL$3:$AL$32,"Yes") | C21: =COUNTIFS('Clean cases'!$X$3:$X$32,"<>Not checked",'Clean cases'!$AL$3:$AL$32,"Yes") | D21: =IF(C21=0,"-",B21/C21) | E21: =COUNTIFS('Clean cases'!$X$3:$X$32,"Yes",'Clean cases'!$AL$3:$AL$32,"No") | F21: =COUNTIFS('Clean cases'!$X$3:$X$32,"<>Not checked",'Clean cases'!$AL$3:$AL$32,"No") | G21: =IF(F21=0,"-",E21/F21)
A22: Imaging: lung nodules / infiltrates | B22: =COUNTIFS('Clean cases'!$Y$3:$Y$32,"Yes",'Clean cases'!$AL$3:$AL$32,"Yes") | C22: =COUNTIFS('Clean cases'!$Y$3:$Y$32,"<>Not checked",'Clean cases'!$AL$3:$AL$32,"Yes") | D22: =IF(C22=0,"-",B22/C22) | E22: =COUNTIFS('Clean cases'!$Y$3:$Y$32,"Yes",'Clean cases'!$AL$3:$AL$32,"No") | F22: =COUNTIFS('Clean cases'!$Y$3:$Y$32,"<>Not checked",'Clean cases'!$AL$3:$AL$32,"No") | G22: =IF(F22=0,"-",E22/F22)
A23: Heart tests abnormal (ECG / echo / MRI) | B23: =COUNTIFS('Clean cases'!$AE$3:$AE$32,"Yes",'Clean cases'!$AL$3:$AL$32,"Yes") | C23: =COUNTIFS('Clean cases'!$AE$3:$AE$32,"<>Not checked",'Clean cases'!$AL$3:$AL$32,"Yes") | D23: =IF(C23=0,"-",B23/C23) | E23: =COUNTIFS('Clean cases'!$AE$3:$AE$32,"Yes",'Clean cases'!$AL$3:$AL$32,"No") | F23: =COUNTIFS('Clean cases'!$AE$3:$AE$32,"<>Not checked",'Clean cases'!$AL$3:$AL$32,"No") | G23: =IF(F23=0,"-",E23/F23)
A25: Total cases | B25: =COUNTA('Clean cases'!$AL$3:$AL$32)
A26: Sarcoidosis cases | B26: =COUNTIF('Clean cases'!$AL$3:$AL$32,"Yes")
A27: Other-disease cases | B27: =COUNTIF('Clean cases'!$AL$3:$AL$32,"No")
A28: Average age – sarcoidosis | B28: =AVERAGEIFS('Clean cases'!$C$3:$C$32,'Clean cases'!$AL$3:$AL$32,"Yes")
A29: Females – sarcoidosis | B29: =COUNTIFS('Clean cases'!$B$3:$B$32,"Female",'Clean cases'!$AL$3:$AL$32,"Yes")
A30: Males – sarcoidosis | B30: =COUNTIFS('Clean cases'!$B$3:$B$32,"Male",'Clean cases'!$AL$3:$AL$32,"Yes")
A31: Average diagnostic time (months) – sarcoidosis | B31: =AVERAGEIFS('Clean cases'!$AM$3:$AM$32,'Clean cases'!$AL$3:$AL$32,"Yes")
A33: Preliminary – updates automatically when the Clean cases sheet changes. "checked" = cases where the item was recorded (Yes or No).

Sheet Original (her text)
A1: case | B1: gender | C1: age | D1: Diagnostic time | E1: diffuse joint pain , low back pain | F1: night sweats | G1: fever nad extra fatigue | H1: Severe abdominal pain | I1: chronic diarrhea | J1: nausea, vomiting | K1: weight loss | L1: Splenomegaly (spleen enlargment ) | M1: Hepatomegaly( lever enlargment) | N1: jaundice | O1: Lymphadenopathy (lymph enlargement ) | P1: Sino-nasal obstruction(Blocked nose) | Q1: dry cough | R1: Oral ulceration | S1: Diffuse polyneuropath | T1: Progressive dyspnea | U1: Diffuse myalgia | V1: Palpitations and advanced heart block | W1: Intense pruritus & bullous skin lesions on extremities | X1: Granulomas | Y1: Biopsy | Z1: CT Scan | AA1: PET Scan | AB1: CRP | AC1: MRI | AD1: TB GOLD TEST | AE1: ACE | AF1: BALF | AG1: Chest X-ray | AH1: Lactate Dehydrogenase (LDH) | AI1: Electroneuromyography (ENMG) | AJ1: WBC | AK1: Ophthalmologic Examination Result | AL1: Tuberculin Skin Test (TST)1 | AM1: Suppressed PTH | AN1: Electrocardiogram (ECG) Result | AO1: Endoscopy | AP1: Transthoracic & Transesophageal Echocardiography | AQ1: Cardiac Biomarkers | AR1: Echocardiogram Result | AS1: Cardiac Magnetic Resonance (CMR) | AT1: Liver Function Tests | AU1: CSF Analysis | AV1: final confirmed | AW1: name of the confirmed disease
A2: 1 | B2: Male | C2: 56 | D2: 4 weeks | E2: not checked | F2: not checked | G2: Yes | H2: Not Checked | I2: Not Checked | J2: Not Checked | K2: Not Checked | L2: Not Checked | M2: Not Checked | N2: Not Checked | O2: No | P2: Not Checked | Q2: no | R2: no | S2: not checked | T2: not checked | U2: not checked | V2: not checked | W2: not checked | X2: Not checkhed | Y2: Not checkhed | Z2: Not checkhed | AA2: Not checkhed | AB2: Not checkhed | AC2: Not checkhed | AD2: Not checkhed | AE2: Not checkhed | AF2: Not checkhed | AG2: not checked | AH2: not checked | AI2: not checked | AJ2: not checked | AK2: not checked | AL2: not checked | AM2: not checked | AN2: not checked | AO2: not checked | AP2: not checked | AQ2: not checked | AR2: not checked | AS2: not checked | AT2: not checked | AU2: not checked | AV2: not confirmed | AW2: Tularemia
A3: 2 | B3: Female | C3: 55 | D3: 5 month | E3: not checked | F3: not checked | G3: Yes | H3: Not Checked | I3: Not Checked | J3: Not Checked | K3: Not Checked | L3: Not Checked | M3: Yes | N3: Not Checked | O3: No | P3: Not Checked | Q3: no | R3: no | S3: not checked | T3: not checked | U3: not checked | V3: not checked | W3: not checked | X3: Not checkhed | Y3: Not checkhed | Z3: Not checkhed | AA3: Not checkhed | AB3: Not checkhed | AC3: Not checkhed | AD3: Not checkhed | AE3: Not checkhed | AF3: Not checkhed | AG3: not checked | AH3: not checked | AI3: not checked | AJ3: not checked | AK3: not checked | AL3: not checked | AM3: not checked | AN3: not checked | AO3: not checked | AP3: not checked | AQ3: not checked | AR3: not checked | AS3: not checked | AT3: not checked | AU3: not checked | AV3: not confirmed | AW3: Cat scratch disease
A4: 3 | B4: Male | C4: 45 | D4: 24 month | E4: not checked | F4: not checked | G4: Yes | H4: Not Checked | I4: Not Checked | J4: Not Checked | K4: Yes | L4: Not Checked | M4: No | N4: Not Checked | O4: Yes | P4: Yes | Q4: no | R4: no | S4: not checked | T4: not checked | U4: not checked | V4: not checked | W4: not checked | X4: Not checkhed | Y4: Not checkhed | Z4: Not checkhed | AA4: Not checkhed | AB4: Not checkhed | AC4: Not checkhed | AD4: Not checkhed | AE4: Not checkhed | AF4: Not checkhed | AG4: not checked | AH4: not checked | AI4: not checked | AJ4: not checked | AK4: not checked | AL4: not checked | AM4: not checked | AN4: not checked | AO4: not checked | AP4: not checked | AQ4: not checked | AR4: not checked | AS4: not checked | AT4: not checked | AU4: not checked | AV4: not confirmed | AW4: Hodgkin’s lymphoma
A5: 4 | B5: Female | C5: 56 | D5: 72 months | E5: not checked | F5: not checked | G5: Yes | H5: Not Checked | I5: Not Checked | J5: Not Checked | K5: Not Checked | L5: Not Checked | M5: No | N5: Not Checked | O5: No | P5: No | Q5: no | R5: no | S5: not checked | T5: not checked | U5: not checked | V5: not checked | W5: not checked | X5: Not checkhed | Y5: Not checkhed | Z5: Not checkhed | AA5: Not checkhed | AB5: Not checkhed | AC5: Not checkhed | AD5: Not checkhed | AE5: Not checkhed | AF5: Not checkhed | AG5: not checked | AH5: not checked | AI5: not checked | AJ5: not checked | AK5: not checked | AL5: not checked | AM5: not checked | AN5: not checked | AO5: not checked | AP5: not checked | AQ5: not checked | AR5: not checked | AS5: not checked | AT5: not checked | AU5: not checked | AV5: not confirmed | AW5: Biclonal Lymphoma
A6: 5 | B6: Male | C6: 70 | D6: 8 to 12 months | E6: not checked | F6: not checked | G6: Yes | H6: Not Checked | I6: Not Checked | J6: Not Checked | K6: Not Checked | L6: Not Checked | M6: No | N6: Not Checked | O6: No | P6: No | Q6: yes | R6: yes | S6: not checked | T6: not checked | U6: not checked | V6: not checked | W6: not checked | X6: ithout granuloma | Y6: first :finding giant-cell granuloma(oral), second:non-necrotizing giant-cell granuloma | Z6: interstitial lung disease, Diffuse micronodules, Retractive consolidations, Traction bronchiectasis, No mediastino-hilar adenopathy | AA6: Not checkhed | AB6: 16.9 | AC6: (Jaw)Left mandibular lesion extending to cheek, with numerous enlarged lymph nodes. | AD6: Positive (5.66 | AE6: Normal | AF6: Positive for Mycobacterium tuberculosis | AG6: not checked | AH6: not checked | AI6: not checked | AJ6: not checked | AK6: not checked | AL6: not checked | AM6: not checked | AN6: not checked | AO6: not checked | AP6: not checked | AQ6: not checked | AR6: not checked | AS6: not checked | AT6: not checked | AU6: not checked | AV6: not confirmed | AW6: pulmonary tuberculosis
A7: 6 | B7: Male | C7: 66 | D7: 2 months | E7: not checked | F7: not checked | G7: Yes | H7: Not Checked | I7: Not Checked | J7: Not Checked | K7: Not Checked | L7: Not Checked | M7: No | N7: Not Checked | O7: No | P7: No | Q7: yes | R7: no | S7: yes | T7: not checked | U7: yes | V7: not checked | W7: yes | X7: No evidence of hemopathy (from spinal cord ) | Y7: Cervical Lymph Node Biopsy(Pyoepithelioid inflammation with partial necrosis و and histiocytes, without giant cells; negative universal PCR and specific cultures),Hodgkin’s disease of scleronodular subtype | Z7: Multiple mediastinal adenopathies (largest in Barety's space measuring 23 mm), cervical adenopathies, and aspecific pulmonary micronodules | AA7: Not checkhed | AB7: 100–220 | AC7: (Brain ) Unremarkable | AD7: Not checkhed | AE7: 36.9 | AF7: Negative for Mtb,90% (Lymphocytic Alveolitis), CD4/CD8=1.27 | AG7: normal | AH7: 284 | AI7: Diffuse axonal polyneuropathy | AJ7: not checked | AK7: not checked | AL7: not checked | AM7: not checked | AN7: not checked | AO7: not checked | AP7: not checked | AQ7: not checked | AR7: not checked | AS7: not checked | AT7: not checked | AU7: Mild hyperproteinorachia (0.7 ) | AV7: not confirmed | AW7: Hodgkin’s lymphoma
A8: 7 | B8: Female | C8: 9 months | D8: 8 months | E8: not checked | F8: not checked | G8: Yes | H8: Not Checked | I8: Not Checked | J8: Not Checked | K8: Not Checked | L8: Not Checked | M8: Not Checked | N8: Not Checked | O8: Not Checked | P8: Not Checked | Q8: not checked | R8: not checked | S8: not checked | T8: not checked | U8: no | V8: not checked | W8: yes | X8: Erythema nodosum on the right flexor forearm (appeared at 1 year of age) | Y8: non-caseating granulomas | Z8: normal chest | AA8: Not checkhed | AB8: 6.56 | AC8: not checked | AD8: not checked | AE8: 14.2 (Normal) | AF8: not checked | AG8: not checked | AH8: not checked | AI8: not checked | AJ8: 15000 | AK8: normal | AL8: negative | AM8: yes | AN8: not checked | AO8: not checked | AP8: not checked | AQ8: not checked | AR8: not checked | AS8: not checked | AT8: not checked | AU8: not checked | AV8: confirmed sarcoidosis | AW8: Early-Onset Sarcoidosis (EOS)
A9: 8 | B9: Female | C9: 45 | D9: 5 years | E9: not checked | F9: not checked | G9: Yes | H9: Yes | I9: Yes | J9: Not Checked | K9: Yes | L9: Not Checked | M9: Not Checked | N9: Not Checked | O9: Not Checked | P9: Not Checked | Q9: not checked | R9: not checked | S9: not checked | T9: not checked | U9: not checked | V9: not checked | W9: not checked | X9: Non-caseating granulomas | Y9: Renal Biopsy( Diffuse acute granulomatous interstitial nephritis),Splenic Biopsy (Non-caseating granulomas) | Z9: Mildly enlarged mediastinal lymph nodes bilaterally; no significant lung parenchymal lesions | AA9: Increased FDG avidity in the spleen and large intestine , 2nd Repeat PET Scan (after immunosuppression failure) Result: Intense FDG avidity in loops of small and large intestines | AB9: not checked | AC9: not checked | AD9: not checked | AE9: Not checkhed | AF9: Not checkhed | AG9: not checked | AH9: not checked not checked | AI9: not checked | AJ9: not checked | AK9: not checked | AL9: not checked | AM9: not checked | AN9: not checked | AO9: not checked | AP9: not checked | AQ9: not checked | AR9: not checked | AS9: not checked | AT9: not checked | AU9: not checked | AV9: not confirmed | AW9: Whipple’s Disease
A10: 9 | B10: Male | C10: 58 | D10: 1 month | E10: not checked | F10: not checked | G10: No | H10: No | I10: No | J10: Not Checked | K10: No | L10: Not Checked | M10: No | N10: Not Checked | O10: No | P10: No | Q10: no | R10: no | S10: no | T10: yes | U10: no | V10: not checked | W10: no | X10: not checked | Y10: Lymph Node Biopsy (EBUS-guided) Result: Negative for granulomatous disease or sarcoidosis | Z10: not checked | AA10: Significantly increased FDG uptake in RV wall and LV, plus focal extracardiac FDG uptake in a paratracheal lymph node (mimicking Cardiac Sarcoidosis) | AB10: not checked | AC10: not checked | AD10: not checked | AE10: not checked | AF10: not checked | AG10: First-degree AV block, high-degree AV block, and morphologically distinct premature ventricular contractions (PVCs) | AH10: not checked | AI10: not checked | AJ10: not checked | AK10: not checked | AL10: not checked | AM10: not checked | AN10: First-degree AV block, T-wave inversions in leads V1–V3, fragmented QRS (epsilon waves) in leads V2–V3, and atrial flutter | AO10: not checked | AP10: evere dilation and markedly reduced systolic function of the right ventricle (RV), severe tricuspid regurgitation, normal interatrial septum | AQ10: not checked | AR10: not checked | AS10: Biventricular involvement (RV EF: 26%, LV EF: 44%), focal RV free wall dyskinesia, extensive epicardial and midmyocardial late gadolinium enhancement (LGE) | AT10: not checked | AU10: not checked | AV10: not confirmed | AW10: Biventricular Arrhythmogenic Cardiomyopathy (AC)
A11: 10 | B11: Male | C11: 50 | D11: 2 years | E11: not checked | F11: not checked | G11: No | H11: No | I11: No | J11: Not Checked | K11: No | L11: Not Checked | M11: No | N11: Not Checked | O11: No | P11: No | Q11: no | R11: no | S11: no | T11: yes | U11: no | V11: yes | W11: no | X11: Not checkhed | Y11: Not checkhed | Z11: Not checkhed | AA11: Focal FDG uptake in the ventricular septum (mimicking Cardiac Sarcoidosis) | AB11: not checked | AC11: not checked | AD11: not checked | AE11: not checked | AF11: not checked | AG11: Initial ECG (Age 48) Result: First-degree AV block, high-degree AV block, and morphologically distinct premature ventricular contractions (PVCs) | AH11: not checked | AI11: not checked | AJ11: not checked | AK11: not checked | AL11: not checked | AM11: not checked | AN11: not checked | AO11: not checked | AP11: not checked | AQ11: not checked | AR11: Reduced LVEF (38%), hypokinesis of septal and posterior LV walls | AS11: Linear mid-wall late gadolinium enhancement (LGE) in the septum, with high T2 signal indicating myocardial inflammation | AT11: not checked | AU11: not checked | AV11: not confirmed | AW11: Genetic Dilated Cardiomyopathy
A12: 11 | B12: Female | C12: 42 | D12: 6 months | E12: yes | F12: yes | G12: Yes | H12: No | I12: No | J12: Not Checked | K12: No | L12: Not Checked | M12: No | N12: Not Checked | O12: No | P12: No | Q12: no | R12: no | S12: no | T12: no | U12: no | V12: no | W12: no | X12: not checked | Y12: Lymph Node & Iliac Bone Biopsies Result: Non-caseating granulomatous inflammation without malignancy | Z12: not checked | AA12: Hypermetabolic pulmonary nodules (right upper lobe), bilateral hilar, mediastinal, and supraclavicular lymphadenopathy, plus focal uptake in right iliac bone, sacrum, and L4 vertebra (mimicking metastatic cancer) | AB12: not checked | AC12: not checked | AD12: not checked | AE12: 70 | AF12: not checked | AG12: not checked | AH12: not checked | AI12: not checked | AJ12: not checked | AK12: not checked | AL12: not checked | AM12: not checked | AN12: not checked | AO12: not checked | AP12: not checked | AQ12: not checked | AR12: not checked | AS12: not checked | AT12: not checked | AU12: not checked | AV12: confirmed sarcoidosis | AW12: Multisystem Sarcoidosis with Axial Skeleton Involvement.
A13: 12 | B13: Female | C13: 44 | D13: 8 weeks | E13: yes | F13: no | G13: No | H13: No | I13: No | J13: Not Checked | K13: No | L13: Not Checked | M13: No | N13: Not Checked | O13: No | P13: No | Q13: no | R13: no | S13: no | T13: no | U13: no | V13: no | W13: no | X13: not checked | Y13: Biopsy of Gluteal Ulcer Result: Non-necrotizing granuloma with granulation tissue fibrosis | Z13: Chest CT & Bloods (negative for systemic organ involvement) | AA13: not checked | AB13: not checked | AC13: not checked | AD13: not checked | AE13: not checked | AF13: not checked | AG13: not checked | AH13: not checked | AI13: not checked | AJ13: not checked | AK13: not checked | AL13: not checked | AM13: not checked | AN13: not checked | AO13: not checked | AP13: not checked | AQ13: not checked | AR13: not checked | AS13: not checked | AT13: not checked | AU13: not checked | AV13: confirmed sarcoidosis | AW13: Isolated Ulcerative Cutaneous Sarcoidosis.
A14: 13 | B14: Female | C14: 71 | D14: 13 years | E14: not checked | F14: not checked | G14: Not Checked | H14: Not Checked | I14: Not Checked | J14: Not Checked | K14: Not Checked | L14: Not Checked | M14: Not Checked | N14: Not Checked | O14: Not Checked | P14: Not Checked | Q14: not checked | R14: not checked | S14: not checked | T14: not checked | U14: not checked | V14: yes | W14: not checked | X14: not checked | Y14: Lymph Node Biopsy (EBUS-TBNA) Result: Non-caseating epithelioid cell granulomas | Z14: Abnormal intense FDG accumulation in cardiac myocardium and hilar lymph node | AA14: not checked | AB14: not checked | AC14: not checked | AD14: not checked | AE14: Normal | AF14: not checked | AG14: not checked | AH14: not checked | AI14: not checked | AJ14: not checked | AK14: not checked | AL14: not checked | AM14: not checked | AN14: Thinning of mid-anteroseptal and basal inferior LV walls | AO14: not checked | AP14: not checked | AQ14: Elevated (NT-proBNP: 357 pg/mL, BNP: 88.4 pg/mL) | AR14: not checked | AS14: not checked | AT14: not checked | AU14: not checked | AV14: confirmed sarcoidosis | AW14: Cardiac Sarcoidosis with Ulcerative Colitis.
A15: 14 | B15: Female | C15: 70 | D15: 3years | E15: no | F15: no | G15: Yes | H15: No | I15: No | J15: Not Checked | K15: Not Checked | L15: Not Checked | M15: Not Checked | N15: Not Checked | O15: Not Checked | P15: Not Checked | Q15: not checked | R15: not checked | S15: not checked | T15: yes | U15: not checked | V15: yes | W15: not checked | X15: not checked | Y15: Lymph Node Biopsy (Non-caseating granulomas) | Z15: not checked | AA15: Negative in heart | AB15: not checked | AC15: (cardiac )Severe RV dilation & dysfunction (RVEF: 14%), LVEF: 43%, late gadolinium enhancement in anteroseptal LV and RV | AD15: not checked | AE15: not checked | AF15: CD4/CD8 ratio elevated at 9.04 | AG15: not checked | AH15: not checked | AI15: not checked | AJ15: not checked | AK15: not checked | AL15: not checked | AM15: not checked | AN15: entricular tachycardia, epsilon waves in V1–V2, T-wave inversions V1–V6, PR interval 210–230 ms | AO15: not checked | AP15: not checked | AQ15: not checked | AR15: not checked | AS15: not checked | AT15: not checked | AU15: not checked | AV15: confirmed sarcoidosis | AW15: Cardiac Sarcoidosis
A16: 15 | B16: Female | C16: 69 | D16: not determined | E16: not checked | F16: not checked | G16: Not Checked | H16: Yes | I16: Not Checked | J16: Not Checked | K16: Not Checked | L16: Not Checked | M16: Not Checked | N16: Not Checked | O16: Not Checked | P16: Not Checked | Q16: not checked | R16: not checked | S16: not checked | T16: not checked | U16: not checked | V16: not checked | W16: not checked | X16: not checked | Y16: Liver Biopsy (Inconclusive (interface hepatitis, no definite granulomas) | Z16: not checked | AA16: not checked | AB16: not checked | AC16: not checked | AD16: not checked | AE16: not checked | AF16: not checked | AG16: not checked | AH16: not checked | AI16: not checked | AJ16: not checked | AK16: not checked | AL16: not checked | AM16: not checked | AN16: not checked | AO16: not checked | AP16: not checked | AQ16: not checked | AR16: not checked | AS16: not checked | AT16: not checked | AU16: not checked | AV16: confirmed sarcoidosis | AW16: Hepatic Sarcoidosis
A17: 16 | B17: Male | C17: 45 | D17: 3 weeks after failed anti-tuberculosis therapy | E17: not checked | F17: not checked | G17: Yes | H17: No | I17: Not Checked | J17: Not Checked | K17: Yes | L17: Not Checked | M17: Not Checked | N17: Not Checked | O17: Not Checked | P17: Not Checked | Q17: not checked | R17: not checked | S17: not checked | T17: yes | U17: not checked | V17: yes | W17: not checked | X17: not checked | Y17: Lung Biopsies: Non-caseating granulomatous inflammation with surrounding concentric fibrosis; negative for mycobacteria and fungi | Z17: not checked | AA17: Highly FDG-avid right lung masses, pericardial nodules, and left pleural lesions | AB17: not checked | AC17: not checked | AD17: not checked | AE17: not checked | AF17: not checked | AG17: not checked | AH17: not checked | AI17: not checked | AJ17: not checked | AK17: not checked | AL17: not checked | AM17: not checked | AN17: not checked | AO17: not checked | AP17: not checked | AQ17: not checked | AR17: not checked | AS17: not checked | AT17: not checked | AU17: not checked | AV17: confirmed sarcoidosis | AW17: Pleuroparenchymal Sarcoidosis
A18: 17 | B18: Female | C18: 26 | D18: 12 months | E18: yes | F18: not checked | G18: Not Checked | H18: Not Checked | I18: Not Checked | J18: Not Checked | K18: Not Checked | L18: Not Checked | M18: Not Checked | N18: Not Checked | O18: Not Checked | P18: Not Checked | Q18: not checked | R18: not checked | S18: not checked | T18: not checked | U18: not checked | V18: not checked | W18: yes | X18: not checked | Y18: Skin Biopsy (Right shoulder lesion) : Dermatofibroma with associated sarcoidal granulomas | Z18: not checked | AA18: not checked | AB18: not checked | AC18: not checked | AD18: not checked | AE18: not checked | AF18: not checked | AG18: not checked | AH18: not checked | AI18: not checked | AJ18: not checked | AK18: not checked | AL18: not checked | AM18: not checked | AN18: not checked | AO18: not checked | AP18: not checked | AQ18: not checked | AR18: not checked | AS18: not checked | AT18: not checked | AU18: not checked | AV18: confirmed sarcoidosis | AW18: (PPD-like Sarcoidosis)
A19: 18 | B19: Male | C19: 39 | D19: 2 months | E19: Not checked | F19: yes | G19: Yes | H19: Yes | I19: Not checked | J19: Not checked | K19: Not checked | L19: Not checked | M19: Not checked | N19: Not checked | O19: Yes | P19: Not Checked | Q19: not checked | R19: not checked | S19: not checked | T19: not checked | U19: not checked | V19: not checked | W19: not checked | X19: not checked | Y19: Skin Biopsy (Tattoo lines) : Non-caseating granulomas suggestive of sarcoidosis | Z19: not checked | AA19: not checked | AB19: not checked | AC19: Cardiac MRI : Small focus of transmural enhancement in the mid-ventricular anterolateral segment | AD19: not checked | AE19: normal | AF19: not checked | AG19: No evidence of hilar or mediastinal lymphadenopathy | AH19: not checked | AI19: not checked | AJ19: not checked | AK19: not checked | AL19: not checked | AM19: not checked | AN19: oderately reduced left ventricular systolic function (LVEF: 40% | AO19: not checked | AP19: not checked | AQ19: not checked | AR19: not checked | AS19: not checked | AT19: not checked | AU19: not checked | AV19: confirmed sarcoidosis | AW19: Tattoo Sarcoidosis with coexisting nonspecific myocarditis
A20: 19 | B20: Female | C20: 56 | D20: 5 months | E20: No | F20: No | G20: No | H20: No | I20: Yes | J20: Yes | K20: No | L20: Not checked | M20: No | N20: Yes | O20: No | P20: No | Q20: yes | R20: no | S20: no | T20: yes | U20: not checked | V20: not checked | W20: no | X20: not checked | Y20: Lymph Node Biopsy:Scattered nodular elevations in trachea/bronchi; EBUS-guided needle aspiration showed non-caseating epithelioid granulomas | Z20: Scattered nodules in both lungs with atelectasis; enlarged retroperitoneal and mediastinal lymph nodes (groups 4R and 7); and a space-occupying mass in the head of the pancreas | AA20: not checked | AB20: not checked | AC20: not checked | AD20: not checked | AE20: not checked | AF20: not checked | AG20: not checked | AH20: not checked | AI20: not checked | AJ20: not checked | AK20: not checked | AL20: not checked | AM20: not checked | AN20: not checked | AO20: not checked | AP20: not checked | AQ20: not checked | AR20: not checked | AS20: not checked | AT20: not checked | AU20: not checked | AV20: confirmed sarcoidosis | AW20: Pancreatic Sarcoidosis
A21: 20 | B21: Female | C21: 56 | D21: several weeks | E21: Yes | F21: No | G21: No | H21: No | I21: No | J21: Yes | K21: No | L21: Not checked | M21: No | N21: Yes | O21: No | P21: No | Q21: no | R21: no | S21: no | T21: no | U21: no | V21: no | W21: no | X21: not checked | Y21: Biopsy Result: Multiple enlarged lymph nodes in porta hepatis (largest 28x26 mm); Fine Needle Biopsy: Porta hepatis lymph node biopsy confirmed sarcoid-like granulomas, Targeted Biopsy Result: Abnormal mucosa with irregularity and nodularity; targeted biopsy demonstrated reactive ductal epithelial cells with non-caseating granulomas | Z21: Moderate central intrahepatic biliary ductal dilatation with compression of common hepatic duct by enlarged porta hepatis lymph nodes; enlarged retroperitoneal/para-aortic nodes; scattered calcified lesions in liver and spleen | AA21: not checked | AB21: not checked | AC21: not checked | AD21: not checked | AE21: not checked | AF21: not checked | AG21: not checked | AH21: not checked | AI21: not checked | AJ21: not checked | AK21: not checked | AL21: not checked | AM21: not checked | AN21: not checked | AO21: not checked | AP21: not checked | AQ21: not checked | AR21: not checked | AS21: not checked | AT21: Total bilirubin 8.4 mg/dL, conjugated bilirubin 7.5 mg/dL, ALP 606 IU/L, AST 107 IU/L, ALT 189 IU/L | AU21: not checked | AV21: confirmed sarcoidosis | AW21: Biliary Sarcoidosis
A22: 21 | B22: Female | C22: 64 | D22: 6 months | E22: Not checked | F22: Not checked | G22: Not checked | H22: Not checked | I22: Not checked | J22: Not checked | K22: Not checked | L22: Not checked | M22: Not checked | N22: Not checked | O22: Not checked | P22: Yes | Q22: not checked | R22: not checked | S22: not checked | T22: yes | U22: not checked | V22: not checked | W22: not checked | X22: not checked | Y22: Nasal Tissue Biopsy:Non-necrotizing granulomas with classic multinucleated histiocytes on right septum and left inferior turbinate, consistent with sarcoidosis | Z22: not checked | AA22: not checked | AB22: not checked | AC22: not checked | AD22: not checked | AE22: not checked | AF22: not checked | AG22: not checked | AH22: not checked | AI22: not checked | AJ22: not checked | AK22: not checked | AL22: not checked | AM22: not checked | AN22: not checked | AO22: Nasal Endoscopy :1 cm firm, highly vascular nasal lesion causing complete right-sided obstruction, with bilateral inferior turbinate enlargement. | AP22: not checked | AQ22: not checked | AR22: not checked | AS22: not checked | AT22: not checked | AU22: not checked | AV22: confirmed sarcoidosis | AW22: Sinonasal Sarcoidosis
A23: 22 | B23: Male | C23: 54 | D23: 1 month | E23: Yes | F23: Not checked | G23: Not checked | H23: Yes | I23: Not checked | J23: Not checked | K23: Not checked | L23: Not checked | M23: Not checked | N23: Not checked | O23: Not checked | P23: Not Checked | Q23: yes | R23: not checked | S23: not checked | T23: not checked | U23: not checked | V23: not checked | W23: no | X23: not checked | Y23: Liver Needle Core Biopsy :Liver almost entirely replaced by non-caseating granulomas with giant cells; PAS, GMS, and AFB negative. | Z23: Multisite lymphadenopathy ,Left adrenal thickening ,Widespread lytic bone lesions ,Chest CT Scan (without contrast) Result: Diffuse 5 mm pulmonary nodular pattern compatible with sarcoidosis | AA23: Pulmonary nodules and liver lesions | AB23: -52 | AC23: Lumbar Spine MRI :Diffuse metastatic osteolytic bone lesions in lumbar and dorsal spine with L5-S1 disc impingement on S1 nerve root | AD23: not checked | AE23: level (102.2 ) | AF23: not checked | AG23: not checked | AH23: not checked | AI23: not checked | AJ23: not checked | AK23: not checked | AL23: not checked | AM23: not checked | AN23: not checked | AO23: not checked | AP23: not checked | AQ23: not checked | AR23: not checked | AS23: not checked | AT23: not checked | AU23: not checked | AV23: confirmed sarcoidosis | AW23: Multisystem Sarcoidosis (Pulmonary, Hepatic, Osseous, Lymphatic, Adrenal)
A24: 23 | B24: Female | C24: 80s | D24: 6 months | E24: No | F24: Not checked | G24: Not checked | H24: Not checked | I24: Not checked | J24: Not checked | K24: Not checked | L24: Not checked | M24: Not checked | N24: Not checked | O24: Not checked | P24: Not Checked | Q24: not checked | R24: not checked | S24: not checked | T24: not checked | U24: not checked | V24: not checked | W24: yes | X24: not checked | Y24: Skin Biopsy:Malignant melanoma (Breslow thickness 5.1 mm, pT4aN0M0); negative sentinel lymph node biopsy | Z24: Lytic lesion in the left fibular head | AA24: FDG-avid lesion | AB24: not checked | AC24: not checked | AD24: not checked | AE24: not checked | AF24: not checked | AG24: not checked | AH24: not checked | AI24: not checked | AJ24: not checked | AK24: not checked | AL24: not checked | AM24: not checked | AN24: not checked | AO24: not checked | AP24: not checked | AQ24: not checked | AR24: not checked | AS24: not checked | AT24: not checked | AU24: not checked | AV24: confirmed sarcoidosis | AW24: Osseous Sarcoidosis of the fibula
A25: 24 | B25: Female | C25: 48 | D25: 1year | E25: Yes | F25: Not checked | G25: Yes | H25: No | I25: Not checked | J25: Not checked | K25: Not checked | L25: Not checked | M25: Not checked | N25: Not checked | O25: Not checked | P25: Not Checked | Q25: not checked | R25: yes | S25: not checked | T25: not checked | U25: not checked | V25: not checked | W25: yes | X25: not checked | Y25: Biopsies (Skin, Gingiva, & Labial Mucosa) Result: Non-caseating granulomas in dermis and lamina propria | Z25: not checked | AA25: not checked | AB25: not checked | AC25: not checked | AD25: not checked | AE25: 60 | AF25: not checked | AG25: Normal chest, jaws, GI, and cardiovascular system | AH25: not checked | AI25: not checked | AJ25: not checked | AK25: not checked | AL25: not checked | AM25: not checked | AN25: not checked | AO25: not checked | AP25: not checked | AQ25: not checked | AR25: not checked | AS25: not checked | AT25: not checked | AU25: not checked | AV25: confirmed sarcoidosis | AW25: Cutaneous and Oral Sarcoidosis
A26: 25 | B26: Female | C26: adult | D26: not determined | E26: Yes | F26: Not checked | G26: Yes | H26: Yes | I26: Not checked | J26: Not checked | K26: Not checked | L26: Yes | M26: Not checked | N26: Not checked | O26: Not checked | P26: Not Checked | Q26: not checked | R26: not checked | S26: not checked | T26: not checked | U26: not checked | V26: not checked | W26: not checked | X26: not checked | Y26: Not checkhed | Z26: Enlarged spleen with a hypoechoic nodule. | AA26: not checked | AB26: not checked | AC26: Heterogeneous enlarged spleen | AD26: not checked | AE26: not checked | AF26: not checked | AG26: not checked | AH26: not checked | AI26: not checked | AJ26: not checked | AK26: not checked | AL26: not checked | AM26: not checked | AN26: not checked | AO26: not checked | AP26: not checked | AQ26: not checked | AR26: not checked | AS26: not checked | AT26: not checked | AU26: not checked | AV26: confirmed sarcoidosis | AW26: Isolated Splenic Sarcoidosis.
A27: 26 | B27: Female | C27: 66 | D27: 2months | E27: No | F27: No | G27: Yes | H27: No | I27: No | J27: Yes | K27: Yes | L27: No | M27: Not checked | N27: Not checked | O27: Not checked | P27: Not Checked | Q27: not checked | R27: not checked | S27: not checked | T27: not checked | U27: not checked | V27: not checked | W27: not checked | X27: not checked | Y27: Bone Marrow Biopsy Result: Negative for neoplasia, primary tumor, or infection , Tissue Histology Result: Confirmed chronic granulomatous lesions | Z27: chest :Negative for neoplasia, primary tumor, or infection. | AA27: not checked | AB27: not checked | AC27: not checked | AD27: not checked | AE27: not checked | AF27: not checked | AG27: not checked | AH27: not checked | AI27: not checked | AJ27: not checked | AK27: not checked | AL27: not checked | AM27: not checked | AN27: not checked | AO27: not checked | AP27: not checked | AQ27: not checked | AR27: not checked | AS27: not checked | AT27: not checked | AU27: not checked | AV27: confirmed sarcoidosis | AW27: Hepato-Splenic Sarcoidosis
